Training data shape: torch.Size([32, 3, 224, 224])
Inside training loop - inputs shape: torch.Size([32, 3, 224, 224])
2024-04-24 22:48:52,638 - INFO - Epoch 1/2
2024-04-24 22:48:52,638 - INFO - ----------
Traceback (most recent call last):
  File "C:\Users\marie\Desktop\Sanfour\MFRS\models\models_train.py", line 278, in <module>
    model_ft = train_model(model, criterion, optimizer_ft, exp_lr_scheduler, args.num_epochs, dataset_loader, dataset_sizes, wandb)
  File "C:\Users\marie\Desktop\Sanfour\MFRS\models\models_train.py", line 97, in train_model
    loss = criterion(outputs, labels)  # Calculate loss
  File "C:\Users\marie\AppData\Roaming\Python\Python39\site-packages\torch\nn\modules\module.py", line 1511, in _wrapped_call_impl
    return self._call_impl(*args, **kwargs)
  File "C:\Users\marie\AppData\Roaming\Python\Python39\site-packages\torch\nn\modules\module.py", line 1520, in _call_impl
    return forward_call(*args, **kwargs)
  File "C:\Users\marie\AppData\Roaming\Python\Python39\site-packages\torch\nn\modules\loss.py", line 1179, in forward
    return F.cross_entropy(input, target, weight=self.weight,
  File "C:\Users\marie\AppData\Roaming\Python\Python39\site-packages\torch\nn\functional.py", line 3059, in cross_entropy
    return torch._C._nn.cross_entropy_loss(input, target, weight, _Reduction.get_enum(reduction), ignore_index, label_smoothing)
IndexError: Target 4585 is out of bounds.
Traceback (most recent call last):
  File "C:\Users\marie\Desktop\Sanfour\MFRS\models\models_train.py", line 278, in <module>
    model_ft = train_model(model, criterion, optimizer_ft, exp_lr_scheduler, args.num_epochs, dataset_loader, dataset_sizes, wandb)
  File "C:\Users\marie\Desktop\Sanfour\MFRS\models\models_train.py", line 97, in train_model
    loss = criterion(outputs, labels)  # Calculate loss
  File "C:\Users\marie\AppData\Roaming\Python\Python39\site-packages\torch\nn\modules\module.py", line 1511, in _wrapped_call_impl
    return self._call_impl(*args, **kwargs)
  File "C:\Users\marie\AppData\Roaming\Python\Python39\site-packages\torch\nn\modules\module.py", line 1520, in _call_impl
    return forward_call(*args, **kwargs)
  File "C:\Users\marie\AppData\Roaming\Python\Python39\site-packages\torch\nn\modules\loss.py", line 1179, in forward
    return F.cross_entropy(input, target, weight=self.weight,
  File "C:\Users\marie\AppData\Roaming\Python\Python39\site-packages\torch\nn\functional.py", line 3059, in cross_entropy
    return torch._C._nn.cross_entropy_loss(input, target, weight, _Reduction.get_enum(reduction), ignore_index, label_smoothing)
IndexError: Target 4585 is out of bounds.
Inside training loop - inputs shape: torch.Size([32, 3, 224, 224])